Workbook

Sheet 说明统计
A1: 项目 | B1: 内容
A2: 文档版本 | B2: 需求分析文档 V2.0；设计文档 V2.0；测试计划 V2.0；用例与执行台账 V1.2
A3: 性质 | B3: 测试用例及实际执行台账；计划关联不代表全部测试通过
A4: 用例数 | B4: 158
A5: 已通过 | B5: =COUNTIF(执行记录!G2:G159,"PASS")
A6: 失败 | B6: =COUNTIF(执行记录!G2:G159,"FAIL")
A7: 阻塞 | B7: =COUNTIF(执行记录!G2:G159,"BLOCKED")
A8: 未执行 | B8: =COUNTIF(执行记录!G2:G159,"NOT_RUN")
A9: 不适用 | B9: =COUNTIF(执行记录!G2:G159,"NOT_APPLICABLE")
A10: 执行覆盖率 | B10: =(B5+B6)/B4
A11: 使用方法 | B11: 执行记录每用例一个当前状态；每次执行完整证据按runId归档，另在执行历史追加。统计仅当前状态。
A12: 通过要求 | B12: 前置数据满足、操作完整、业务与数据库断言通过、证据齐全；不能只依据HTTP200
A13: P0退出要求 | B13: 全部P0通过；S1/S2清零；环境容量不足或缺少7天观测应记录验收缺口
A14: 角色 | B14: R1组长/集成；R2学生/目录；R3教师/成绩；R4人员/认证/前端；R5测试/关闭/计费；实际成员据实映射
A15: 引用 | B15: 主文档附录D官方资料；工具版本在环境登记记录实际安装值
A16: 重要区分 | B16: 158条为测试用例规格，不是158条已执行测试；模型推演不作为系统测试结果
A17: 用例构成 | B17: 158条用例，保留原编号及执行记录
A18: 完整追踪 | B18: 25FR+16BR+3SEC+5DATA+12NFR+17AC=78项；计划关联不代表实际通过
A19: 通过率 | B19: =IFERROR(B5/(B5+B6),"")
A20: 参数化要求 | B20: 多参数用例必须各variant通过才能同步整条PASS；执行历史保留首次FAIL
A21: PDF说明 | B21: 独立排版阅读版，内容相同，分页可与Word不同；Word目录可更新
A22: V1.2执行说明 | B22: PARTIAL表示有实际场景证据，但完整计划用例variant未全部执行。人工复核、158整条PASS和长期指标不得由自动记录推定。
A23: PARTIAL条目 | B23: =COUNTIF(执行记录!G2:G159,"PARTIAL")

Sheet 用例库
A1: 用例编号 | B1: 领域 | C1: 标题 | D1: 优先级 | E1: 需求关联 | F1: 验收关联 | G1: 数据集 | H1: 前置与操作 | I1: 预期结果 | J1: 证据要求 | K1: 执行方式 | L1: 复核角色 | M1: 设计关联 | N1: 参数化覆盖要求
A2: TC-AUTH-001 | B2: AUTH | C2: 三角色正确登录 | D2: P0 | E2: FR-01,FR-02 | F2: AC-01,AC-02 | G2: D01,D14 | H2: 按主文档第5章构建独立数据快照；分别提交有效凭据并访问me及角色首页 | I2: 200；身份和角色正确，Session重新生成 | J2: 构建/环境/数据版本、请求与traceId、前后数据库一致性快照；并发附屏障时间线，故障附注入与恢复日志 | K2: 自动化+人工核验 | L2: R3/R5 | M2: 《设计文档_V2.0》第10—11、附录A；业务约束见《需求分析文档_V2.0》第5—7章 | N2: 列举的每个边界/枚举/时刻/浏览器组合均为必测variant；每variant留runId或参数化子结果，全部通过才可将整条标PASS
A3: TC-AUTH-002 | B3: AUTH | C3: 错误凭据与未知账号 | D3: P0 | E3: FR-01 | F3: AC-01 | G3: D01,D14 | H3: 按主文档第5章构建独立数据快照；错误密码、未知用户名、空字段分别登录 | I3: 拒绝且不建立有效Session；提示不泄露账号存在性 | J3: 构建/环境/数据版本、请求与traceId、前后数据库一致性快照；并发附屏障时间线，故障附注入与恢复日志 | K3: 自动化+人工核验 | L3: R3/R5 | M3: 《设计文档_V2.0》第10—11、附录A；业务约束见《需求分析文档_V2.0》第5—7章 | N3: 列举的每个边界/枚举/时刻/浏览器组合均为必测variant；每variant留runId或参数化子结果，全部通过才可将整条标PASS
A4: TC-AUTH-003 | B4: AUTH | C4: 退出与旧Session | D4: P0 | E4: FR-03,SEC-03 | F4: AC-01 | G4: D01,D14 | H4: 按主文档第5章构建独立数据快照；登录后退出，再携带原Cookie访问受保护接口 | I4: 退出成功；旧Session返回401 | J4: 构建/环境/数据版本、请求与traceId、前后数据库一致性快照；并发附屏障时间线，故障附注入与恢复日志 | K4: 自动化+人工核验 | L4: R3/R5 | M4: 《设计文档_V2.0》第10—11、附录A；业务约束见《需求分析文档_V2.0》第5—7章 | N4: 列举的每个边界/枚举/时刻/浏览器组合均为必测variant；每variant留runId或参数化子结果，全部通过才可将整条标PASS
A5: TC-AUTH-004 | B5: AUTH | C5: 首次密码修改门禁 | D5: P0 | G5: D01,D14 | H5: 按主文档第5章构建独立数据快照；用临时密码访问业务，再修改为合规密码 | I5: 业务拒绝；仅me/csrf/logout/password允许；修改后正常使用 | J5: 构建/环境/数据版本、请求与traceId、前后数据库一致性快照；并发附屏障时间线，故障附注入与恢复日志 | K5: 自动化+人工核验 | L5: R3/R5 | M5: 《设计文档_V2.0》第10—11、附录A；业务约束见《需求分析文档_V2.0》第5—7章 | N5: 列举的每个边界/枚举/时刻/浏览器组合均为必测variant；每variant留runId或参数化子结果，全部通过才可将整条标PASS
A6: TC-AUTH-005 | B6: AUTH | C6: 密码复杂度和错误旧密码 | D6: P0 | G6: D01,D14 | H6: 按主文档第5章构建独立数据快照；测试不足12位、错误旧密码及合法新密码 | I6: 非法拒绝且旧凭据不变；合法修改使旧Session失效 | J6: 构建/环境/数据版本、请求与traceId、前后数据库一致性快照；并发附屏障时间线，故障附注入与恢复日志 | K6: 自动化+人工核验 | L6: R3/R5 | M6: 《设计文档_V2.0》第10—11、附录A；业务约束见《需求分析文档_V2.0》第5—7章 | N6: 列举的每个边界/枚举/时刻/浏览器组合均为必测variant；每variant留runId或参数化子结果，全部通过才可将整条标PASS
A7: TC-AUTH-006 | B7: AUTH | C7: 密码重置与凭据版本 | D7: P0 | E7: SEC-03 | G7: D01,D14 | H7: 按主文档第5章构建独立数据快照；管理员重置已在两个浏览器登录的人员 | I7: 只展示一次临时密码；原会话均失效；新登录需改密 | J7: 构建/环境/数据版本、请求与traceId、前后数据库一致性快照；并发附屏障时间线，故障附注入与恢复日志 | K7: 自动化+人工核验 | L7: R3/R5 | M7: 《设计文档_V2.0》第10—11、附录A；业务约束见《需求分析文档_V2.0》第5—7章 | N7: 列举的每个边界/枚举/时刻/浏览器组合均为必测variant；每variant留runId或参数化子结果，全部通过才可将整条标PASS
A8: TC-AUTH-007 | B8: AUTH | C8: 登录限流 | D8: P0 | E8: FR-01 | F8: AC-01 | G8: D01,D14 | H8: 按主文档第5章构建独立数据快照；记录配置阈值并超过阈值重试，再等待恢复 | I8: 达到配置阈值429；正常恢复；无凭据日志泄露 | J8: 构建/环境/数据版本、请求与traceId、前后数据库一致性快照；并发附屏障时间线，故障附注入与恢复日志 | K8: 自动化+人工核验 | L8: R3/R5 | M8: 《设计文档_V2.0》第10—11、附录A；业务约束见《需求分析文档_V2.0》第5—7章 | N8: 列举的每个边界/枚举/时刻/浏览器组合均为必测variant；每variant留runId或参数化子结果，全部通过才可将整条标PASS
A9: TC-AUTH-008 | B9: AUTH | C9: 停用账号与角色导航 | D9: P0 | E9: FR-01,FR-02,SEC-03 | F9: AC-01,AC-02 | G9: D01,D14 | H9: 按主文档第5章构建独立数据快照；停用账号登录；三角色检查导航及直接接口 | I9: 停用拒绝；菜单按角色；隐藏菜单不能绕过服务端权限 | J9: 构建/环境/数据版本、请求与traceId、前后数据库一致性快照；并发附屏障时间线，故障附注入与恢复日志 | K9: 自动化+人工核验 | L9: R3/R5 | M9: 《设计文档_V2.0》第10—11、附录A；业务约束见《需求分析文档_V2.0》第5—7章 | N9: 列举的每个边界/枚举/时刻/浏览器组合均为必测variant；每variant留runId或参数化子结果，全部通过才可将整条标PASS
A10: TC-CAT-001 | B10: CAT | C10: 当前开课班详情 | D10: P0 | E10: FR-04 | F10: AC-03 | G10: D01,D13 | H10: 按主文档第5章构建独立数据快照；查询当前学期开课与详情并对照只读快照 | I10: 课程、院系、教师、时间、先修、容量来源正确 | J10: 构建/环境/数据版本、请求与traceId、前后数据库一致性快照；并发附屏障时间线，故障附注入与恢复日志 | K10: 自动化+人工核验 | L10: R3/R5 | M10: 《设计文档_V2.0》第5、10、12.4；业务约束见《需求分析文档_V2.0》第5—7章 | N10: 列举的每个边界/枚举/时刻/浏览器组合均为必测variant；每variant留runId或参数化子结果，全部通过才可将整条标PASS
A11: TC-CAT-002 | B11: CAT | C11: 搜索分页空结果 | D11: P0 | E11: FR-04,FR-24 | F11: AC-03,AC-16 | G11: D01,D13 | H11: 按主文档第5章构建独立数据快照；关键词命中、无结果、边界页及非法页参数 | I11: 有效结果稳定分页；空结果明确；非法参数拒绝或规范化 | J11: 构建/环境/数据版本、请求与traceId、前后数据库一致性快照；并发附屏障时间线，故障附注入与恢复日志 | K11: 自动化+人工核验 | L11: R3/R5 | M11: 《设计文档_V2.0》第5、10、12.4；业务约束见《需求分析文档_V2.0》第5—7章 | N11: 列举的每个边界/枚举/时刻/浏览器组合均为必测variant；每variant留runId或参数化子结果，全部通过才可将整条标PASS
A12: TC-CAT-003 | B12: CAT | C12: 只读边界 | D12: P0 | E12: BR-11,FR-21 | F12: AC-03 | G12: D01,D13 | H12: 按主文档第5章构建独立数据快照；记录源库SELECT权限并完成查询、授课和选课 | I12: 源库无写权限无写入；名额和教师仅改本地运行表 | J12: 构建/环境/数据版本、请求与traceId、前后数据库一致性快照；并发附屏障时间线，故障附注入与恢复日志 | K12: 自动化+人工核验 | L12: R3/R5 | M12: 《设计文档_V2.0》第5、10、12.4；业务约束见《需求分析文档_V2.0》第5—7章 | N12: 列举的每个边界/枚举/时刻/浏览器组合均为必测variant；每variant留runId或参数化子结果，全部通过才可将整条标PASS
A13: TC-CAT-004 | B13: CAT | C13: 目录故障超时 | D13: P0 | E13: FR-21 | F13: AC-03 | G13: D01,D13 | H13: 按主文档第5章构建独立数据快照；隔离目录依赖和注入超过10秒延迟；区分镜像可用性 | I13: 分别测试完整冻结镜像可用和镜像缺失/实际源调用：前者按设计读镜像；后者依赖流程503/504终止；真实源调用<=10秒；不伪报源调用成功 | J13: 构建/环境/数据版本、请求与traceId、前后数据库一致性快照；并发附屏障时间线，故障附注入与恢复日志 | K13: 自动化+人工核验 | L13: R3/R5 | M13: 《设计文档_V2.0》第5、10、12.4；业务约束见《需求分析文档_V2.0》第5—7章 | N13: 列举的每个边界/枚举/时刻/浏览器组合均为必测variant；每variant留runId或参数化子结果，全部通过才可将整条标PASS
A14: TC-CAT-005 | B14: CAT | C14: 缓存与快照版本 | D14: P0 | E14: BR-11,FR-21 | F14: AC-03 | G14: D01,D13 | H14: 按主文档第5章构建独立数据快照；在准备环境切换合法快照；观察120秒TTL和缓存键 | I14: 同学期冻结版本稳定；新版本无混合字段；动态名额不被静态缓存覆盖 | J14: 构建/环境/数据版本、请求与traceId、前后数据库一致性快照；并发附屏障时间线，故障附注入与恢复日志 | K14: 自动化+人工核验 | L14: R3/R5 | M14: 《设计文档_V2.0》第5、10、12.4；业务约束见《需求分析文档_V2.0》第5—7章 | N14: 列举的每个边界/枚举/时刻/浏览器组合均为必测variant；每variant留runId或参数化子结果，全部通过才可将整条标PASS
A15: TC-CAT-006 | B15: CAT | C15: 构建中变满提示 | D15: P0 | E15: BR-07,FR-25 | F15: AC-06 | G15: D01,D13 | H15: 按主文档第5章构建独立数据快照；学生选中9人班，另一学生填满后继续构建及提交 | I15: 提交处理前显示满员提示；正式提交仍校验并拒绝该班 | J15: 构建/环境/数据版本、请求与traceId、前后数据库一致性快照；并发附屏障时间线，故障附注入与恢复日志 | K15: 自动化+人工核验 | L15: R3/R5 | M15: 《设计文档_V2.0》第5、10、12.4；业务约束见《需求分析文档_V2.0》第5—7章 | N15: 列举的每个边界/枚举/时刻/浏览器组合均为必测variant；每variant留runId或参数化子结果，全部通过才可将整条标PASS
A16: TC-REG-001 | B16: REG | C16: 保存与读取草稿 | D16: P0 | E16: BR-06,BR-13,DATA-02,FR-05,FR-06,FR-10 | F16: AC-04,AC-07 | G16: D01,D02,D03,D04,D05 | H16: 按主文档第5章构建独立数据快照；保存4主2备并重新登录读取 | I16: 顺序保留；不新增ACTIVE、不改变名额；显示draftItems/enrolledItems | J16: 构建/环境/数据版本、请求与traceId、前后数据库一致性快照；并发附屏障时间线，故障附注入与恢复日志 | K16: 自动化+人工核验 | L16: R3/R5 | M16: 《设计文档_V2.0》第6—7；业务约束见《需求分析文档_V2.0》第5—7章 | N16: 列举的每个边界/枚举/时刻/浏览器组合均为必测variant；每variant留runId或参数化子结果，全部通过才可将整条标PASS
A17: TC-REG-002 | B17: REG | C17: 草稿数量边界 | D17: P0 | E17: BR-01,FR-05,FR-06 | F17: AC-04 | G17: D01,D02,D03,D04,D05 | H17: 按主文档第5章构建独立数据快照；保存0项、4主2备以及5主或3备 | I17: 合法草稿保存；超限拒绝且不覆盖原草稿 | J17: 构建/环境/数据版本、请求与traceId、前后数据库一致性快照；并发附屏障时间线，故障附注入与恢复日志 | K17: 自动化+人工核验 | L17: R3/R5 | M17: 《设计文档_V2.0》第6—7；业务约束见《需求分析文档_V2.0》第5—7章 | N17: 列举的每个边界/枚举/时刻/浏览器组合均为必测variant；每variant留runId或参数化子结果，全部通过才可将整条标PASS
A18: TC-REG-003 | B18: REG | C18: 首次正式提交 | D18: P0 | E18: BR-01,BR-13,FR-07,FR-10 | F18: AC-04,AC-05,AC-06,AC-07 | G18: D01,D02,D03,D04,D05 | H18: 按主文档第5章构建独立数据快照；准备合法4主2备并提交 | I18: 4主ACTIVE、备选不占位；名单人数一致；正式快照更新 | J18: 构建/环境/数据版本、请求与traceId、前后数据库一致性快照；并发附屏障时间线，故障附注入与恢复日志 | K18: 自动化+人工核验 | L18: R3/R5 | M18: 《设计文档_V2.0》第6—7；业务约束见《需求分析文档_V2.0》第5—7章 | N18: 列举的每个边界/枚举/时刻/浏览器组合均为必测variant；每variant留runId或参数化子结果，全部通过才可将整条标PASS
A19: TC-REG-004 | B19: REG | C19: 首次数量不足 | D19: P0 | E19: BR-01,FR-05 | F19: AC-04 | G19: D01,D02,D03,D04,D05 | H19: 按主文档第5章构建独立数据快照；新建或DELETED后重建提交3主2备及4主1备 | I19: 拒绝；首次或重建必须恰好4主2备 | J19: 构建/环境/数据版本、请求与traceId、前后数据库一致性快照；并发附屏障时间线，故障附注入与恢复日志 | K19: 自动化+人工核验 | L19: R3/R5 | M19: 《设计文档_V2.0》第6—7；业务约束见《需求分析文档_V2.0》第5—7章 | N19: 列举的每个边界/枚举/时刻/浏览器组合均为必测variant；每variant留runId或参数化子结果，全部通过才可将整条标PASS
... A49: TC-PEOPLE-004 | B49: PEOPLE | C49: 当前关系阻止删除 | D49: P0 | E49: DATA-03,FR-17,FR-19 | F49: AC-11 | G49: D10,D14 | H49: 按主文档第5章构建独立数据快照；对OPEN/CLOSING有ACTIVE或授课关系人员删除 | I49: 409 ACTIVE_RELATION_EXISTS；账号人员关系均不变 | J49: 构建/环境/数据版本、请求与traceId、前后数据库一致性快照；并发附屏障时间线，故障附注入与恢复日志 | K49: 自动化+人工核验 | L49: R3/R5 | M49: 《设计文档_V2.0》第5、10.5、11；业务约束见《需求分析文档_V2.0》第5—7章 | N49: 列举的每个边界/枚举/时刻/浏览器组合均为必测variant；每variant留runId或参数化子结果，全部通过才可将整条标PASS
A50: TC-PEOPLE-005 | B50: PEOPLE | C50: 非活跃状态切换 | D50: P0 | G50: D10,D14 | H50: 按主文档第5章构建独立数据快照；有当前关系切非ENROLLED/非ON_DUTY，解除后再切 | I50: 有关联拒绝；解除后成功；新选课或授课拒绝 | J50: 构建/环境/数据版本、请求与traceId、前后数据库一致性快照；并发附屏障时间线，故障附注入与恢复日志 | K50: 自动化+人工核验 | L50: R3/R5 | M50: 《设计文档_V2.0》第5、10.5、11；业务约束见《需求分析文档_V2.0》第5—7章 | N50: 列举的每个边界/枚举/时刻/浏览器组合均为必测variant；每variant留runId或参数化子结果，全部通过才可将整条标PASS
A51: TC-PEOPLE-006 | B51: PEOPLE | C51: 删除取消与不存在 | D51: P0 | E51: FR-17,FR-19 | F51: AC-11 | G51: D10,D14 | H51: 按主文档第5章构建独立数据快照；取消UI确认；确认不存在ID；重复删除 | I51: 取消无变化；授权范围不存在404；重复删除已删除记录204无体且不重复业务审计 | J51: 构建/环境/数据版本、请求与traceId、前后数据库一致性快照；并发附屏障时间线，故障附注入与恢复日志 | K51: 自动化+人工核验 | L51: R3/R5 | M51: 《设计文档_V2.0》第5、10.5、11；业务约束见《需求分析文档_V2.0》第5—7章 | N51: 列举的每个边界/枚举/时刻/浏览器组合均为必测variant；每variant留runId或参数化子结果，全部通过才可将整条标PASS
A52: TC-PEOPLE-007 | B52: PEOPLE | C52: 创建中途数据库失败 | D52: P0 | E52: FR-16,FR-18 | F52: AC-11 | G52: D10,D14 | H52: 按主文档第5章构建独立数据快照；账号插入阶段注入失败并查人员表 | I52: 人员与账号均回滚；无孤儿或明文密码 | J52: 构建/环境/数据版本、请求与traceId、前后数据库一致性快照；并发附屏障时间线，故障附注入与恢复日志 | K52: 自动化+人工核验 | L52: R3/R5 | M52: 《设计文档_V2.0》第5、10.5、11；业务约束见《需求分析文档_V2.0》第5—7章 | N52: 列举的每个边界/枚举/时刻/浏览器组合均为必测variant；每variant留runId或参数化子结果，全部通过才可将整条标PASS
A53: TC-PEOPLE-008 | B53: PEOPLE | C53: 人员搜索及字段校验 | D53: P0 | E53: FR-16,FR-18,FR-24 | F53: AC-11,AC-16 | G53: D10,D14 | H53: 按主文档第5章构建独立数据快照；分页搜索、非法必填字段、超长字段及重复约束 | I53: 提示明确；不突破唯一约束；不泄露内部SQL | J53: 构建/环境/数据版本、请求与traceId、前后数据库一致性快照；并发附屏障时间线，故障附注入与恢复日志 | K53: 自动化+人工核验 | L53: R3/R5 | M53: 《设计文档_V2.0》第5、10.5、11；业务约束见《需求分析文档_V2.0》第5—7章 | N53: 列举的每个边界/枚举/时刻/浏览器组合均为必测variant；每variant留runId或参数化子结果，全部通过才可将整条标PASS
A54: TC-PEOPLE-009 | B54: PEOPLE | C54: 姓名长度及日期边界 | D54: P1 | E54: FR-16,FR-18 | F54: AC-11 | G54: D10,D14 | H54: 按主文档第5章构建独立数据快照；虚构姓名1/100/101字符及全空白，生日今天/未来/非法日期 | I54: 去空白后1-100合法；非法400且无半记录；业务时区今天可接受 | J54: 构建/环境/数据版本、请求与traceId、前后数据库一致性快照；并发附屏障时间线，故障附注入与恢复日志 | K54: 自动化+人工核验 | L54: R3/R5 | M54: 《设计文档_V2.0》第5、10.5、11；业务约束见《需求分析文档_V2.0》第5—7章 | N54: 列举的每个边界/枚举/时刻/浏览器组合均为必测variant；每variant留runId或参数化子结果，全部通过才可将整条标PASS
A55: TC-PEOPLE-010 | B55: PEOPLE | C55: SSN规范化 | D55: P1 | E55: DATA-04,FR-16,FR-18 | F55: AC-11 | G55: D10,D14 | H55: 按主文档第5章构建独立数据快照；9位数字和带常见分隔符；8/10位及字母 | I55: 合法规范9位；非法拒绝；不增加SSN唯一或实名规则 | J55: 构建/环境/数据版本、请求与traceId、前后数据库一致性快照；并发附屏障时间线，故障附注入与恢复日志 | K55: 自动化+人工核验 | L55: R3/R5 | M55: 《设计文档_V2.0》第5、10.5、11；业务约束见《需求分析文档_V2.0》第5—7章 | N55: 列举的每个边界/枚举/时刻/浏览器组合均为必测variant；每variant留runId或参数化子结果，全部通过才可将整条标PASS
A56: TC-PEOPLE-011 | B56: PEOPLE | C56: 毕业日期与教师字段 | D56: P1 | E56: FR-16,FR-18 | F56: AC-11 | G56: D10,D14 | H56: 按主文档第5章构建独立数据快照；毕业null/生日当天/早于生日/未来计划；院系缺失及非法状态 | I56: 毕业可空可未来但不早于出生；教师院系必填；枚举分人员类型 | J56: 构建/环境/数据版本、请求与traceId、前后数据库一致性快照；并发附屏障时间线，故障附注入与恢复日志 | K56: 自动化+人工核验 | L56: R3/R5 | M56: 《设计文档_V2.0》第5、10.5、11；业务约束见《需求分析文档_V2.0》第5—7章 | N56: 列举的每个边界/枚举/时刻/浏览器组合均为必测variant；每variant留runId或参数化子结果，全部通过才可将整条标PASS
A57: TC-PEOPLE-012 | B57: PEOPLE | C57: 重复逻辑删除幂等 | D57: P0 | E57: DATA-03,FR-17,FR-19 | F57: AC-11 | G57: D10,D14 | H57: 按主文档第5章构建独立数据快照；删除一次再重复删除已删ID并检查审计历史 | I57: 204无业务体；不重复业务删除事件；历史保留账号仍禁用 | J57: 构建/环境/数据版本、请求与traceId、前后数据库一致性快照；并发附屏障时间线，故障附注入与恢复日志 | K57: 自动化+人工核验 | L57: R3/R5 | M57: 《设计文档_V2.0》第5、10.5、11；业务约束见《需求分析文档_V2.0》第5—7章 | N57: 列举的每个边界/枚举/时刻/浏览器组合均为必测variant；每variant留runId或参数化子结果，全部通过才可将整条标PASS
A58: TC-PEOPLE-013 | B58: PEOPLE | C58: 历史仅查权限与停用分离 | D58: P0 | E58: SEC-03 | G58: D10,D14 | H58: 按主文档第5章构建独立数据快照；非ENROLLED读本人历史、非ON_DUTY录历史；DISABLED旧会话请求 | I58: 业务状态保留设计历史权限；账号禁用一律拒绝 | J58: 构建/环境/数据版本、请求与traceId、前后数据库一致性快照；并发附屏障时间线，故障附注入与恢复日志 | K58: 自动化+人工核验 | L58: R3/R5 | M58: 《设计文档_V2.0》第5、10.5、11；业务约束见《需求分析文档_V2.0》第5—7章 | N58: 列举的每个边界/枚举/时刻/浏览器组合均为必测variant；每variant留runId或参数化子结果，全部通过才可将整条标PASS
A59: TC-CLOSE-001 | B59: CLOSE | C59: 正常关闭完整流程 | D59: P0 | E59: FR-20,FR-23 | F59: AC-12,AC-13,AC-15 | G59: D06,D07 | H59: 按主文档第5章构建独立数据快照；管理员提交关闭；轮询至LOCAL_COMMITTED再等待计费 | I59: 202为已受理；一次生成最终课表账单outbox；最终COMPLETE | J59: 构建/环境/数据版本、请求与traceId、前后数据库一致性快照；并发附屏障时间线，故障附注入与恢复日志 | K59: 自动化+人工核验 | L59: R1/R2 | M59: 《设计文档_V2.0》第6、8、附录A；业务约束见《需求分析文档_V2.0》第5—7章 | N59: 列举的每个边界/枚举/时刻/浏览器组合均为必测variant；每variant留runId或参数化子结果，全部通过才可将整条标PASS
A60: TC-CLOSE-002 | B60: CLOSE | C60: 无教师班取消 | D60: P0 | E60: BR-08,FR-20 | F60: AC-12,AC-13,AC-15 | G60: D06,D07 | H60: 按主文档第5章构建独立数据快照；准备无教师不同人数班并关闭 | I60: 全部无教师班取消；正式ACTIVE清零；替补按单遍规则 | J60: 构建/环境/数据版本、请求与traceId、前后数据库一致性快照；并发附屏障时间线，故障附注入与恢复日志 | K60: 自动化+人工核验 | L60: R1/R2 | M60: 《设计文档_V2.0》第6、8、附录A；业务约束见《需求分析文档_V2.0》第5—7章 | N60: 列举的每个边界/枚举/时刻/浏览器组合均为必测variant；每variant留runId或参数化子结果，全部通过才可将整条标PASS
A61: TC-CLOSE-003 | B61: CLOSE | C61: 2人保留至补位与3人有效 | D61: P0 | E61: BR-02,BR-08,FR-20 | F61: AC-12,AC-13,AC-15 | G61: D06,D07 | H61: 按主文档第5章构建独立数据快照；初始2人班有可替补、3人班正常关闭 | I61: 2人班先保留候选；最终>=3存活否则取消；3人班有效 | J61: 构建/环境/数据版本、请求与traceId、前后数据库一致性快照；并发附屏障时间线，故障附注入与恢复日志 | K61: 自动化+人工核验 | L61: R1/R2 | M61: 《设计文档_V2.0》第6、8、附录A；业务约束见《需求分析文档_V2.0》第5—7章 | N61: 列举的每个边界/枚举/时刻/浏览器组合均为必测variant；每variant留runId或参数化子结果，全部通过才可将整条标PASS
A62: TC-CLOSE-004 | B62: CLOSE | C62: 四席替换最高序主选 | D62: P0 | E62: BR-15,FR-20 | F62: AC-12,AC-13,AC-15 | G62: D06,D07 | H62: 按主文档第5章构建独立数据快照；学生4席含未确认主选，设置合法备选 | I62: 假设移除choice_order最高未确认主选后验证；成功才真正替换 | J62: 构建/环境/数据版本、请求与traceId、前后数据库一致性快照；并发附屏障时间线，故障附注入与恢复日志 | K62: 自动化+人工核验 | L62: R1/R2 | M62: 《设计文档_V2.0》第6、8、附录A；业务约束见《需求分析文档_V2.0》第5—7章 | N62: 列举的每个边界/枚举/时刻/浏览器组合均为必测variant；每variant留runId或参数化子结果，全部通过才可将整条标PASS
A63: TC-CLOSE-005 | B63: CLOSE | C63: 备选失败不丢原席 | D63: P0 | E63: BR-03,BR-09,BR-15,FR-20 | F63: AC-12,AC-13,AC-15 | G63: D06,D07 | H63: 按主文档第5章构建独立数据快照；候选满员/先修/时间失败，再给合法第二备选 | I63: 失败不释放原席；顺序1再2；仅合法候选改变计划 | J63: 构建/环境/数据版本、请求与traceId、前后数据库一致性快照；并发附屏障时间线，故障附注入与恢复日志 | K63: 自动化+人工核验 | L63: R1/R2 | M63: 《设计文档_V2.0》第6、8、附录A；业务约束见《需求分析文档_V2.0》第5—7章 | N63: 列举的每个边界/枚举/时刻/浏览器组合均为必测variant；每variant留runId或参数化子结果，全部通过才可将整条标PASS
A64: TC-CLOSE-006 | B64: CLOSE | C64: 不回溯与不重复补位 | D64: P0 | E64: BR-01,BR-09,BR-15,FR-20 | F64: AC-12,AC-13,AC-15 | G64: D06,D07 | H64: 按主文档第5章构建独立数据快照；激活备选后设置后续低人数变化 | I64: 每人每备选最多处理一次；激活备选不作为可替换主选；无第二轮 | J64: 构建/环境/数据版本、请求与traceId、前后数据库一致性快照；并发附屏障时间线，故障附注入与恢复日志 | K64: 自动化+人工核验 | L64: R1/R2 | M64: 《设计文档_V2.0》第6、8、附录A；业务约束见《需求分析文档_V2.0》第5—7章 | N64: 列举的每个边界/枚举/时刻/浏览器组合均为必测variant；每variant留runId或参数化子结果，全部通过才可将整条标PASS
A65: TC-CLOSE-007 | B65: CLOSE | C65: 提交时间及ID排序 | D65: P0 | E65: BR-09,FR-20 | F65: AC-12,AC-13,AC-15 | G65: D06,D07 | H65: 按主文档第5章构建独立数据快照；first_submitted_at相同/不同、重提及同班竞争 | I65: 按首次时间再student_id确定顺序；重提不重置首次时间 | J65: 构建/环境/数据版本、请求与traceId、前后数据库一致性快照；并发附屏障时间线，故障附注入与恢复日志 | K65: 自动化+人工核验 | L65: R1/R2 | M65: 《设计文档_V2.0》第6、8、附录A；业务约束见《需求分析文档_V2.0》第5—7章 | N65: 列举的每个边界/枚举/时刻/浏览器组合均为必测variant；每variant留runId或参数化子结果，全部通过才可将整条标PASS
A66: TC-CLOSE-008 | B66: CLOSE | C66: 草稿删除停用参与过滤 | D66: P0 | E66: FR-20 | F66: AC-12,AC-13,AC-15 | G66: D06,D07 | H66: 按主文档第5章构建独立数据快照；纯草稿、DELETED、停用及退至0门已正式提交参与关闭 | I66: 前3类不自动补位/计费；合格零门提交者参与且可有0金额账单 | J66: 构建/环境/数据版本、请求与traceId、前后数据库一致性快照；并发附屏障时间线，故障附注入与恢复日志 | K66: 自动化+人工核验 | L66: R1/R2 | M66: 《设计文档_V2.0》第6、8、附录A；业务约束见《需求分析文档_V2.0》第5—7章 | N66: 列举的每个边界/枚举/时刻/浏览器组合均为必测variant；每variant留runId或参数化子结果，全部通过才可将整条标PASS
A67: TC-CLOSE-009 | B67: CLOSE | C67: 重复请求同一任务 | D67: P0 | E67: BR-16,FR-20,FR-23 | F67: AC-12,AC-13,AC-15 | G67: D06,D07 | H67: 按主文档第5章构建独立数据快照；并发或重复请求同学期关闭 | I67: 仅一个逻辑close_job；已完成可查询；不新增账单 | J67: 构建/环境/数据版本、请求与traceId、前后数据库一致性快照；并发附屏障时间线，故障附注入与恢复日志 | K67: 自动化+人工核验 | L67: R1/R2 | M67: 《设计文档_V2.0》第6、8、附录A；业务约束见《需求分析文档_V2.0》第5—7章 | N67: 列举的每个边界/枚举/时刻/浏览器组合均为必测variant；每variant留runId或参数化子结果，全部通过才可将整条标PASS
A68: TC-CLOSE-010 | B68: CLOSE | C68: 提交前异常回滚 | D68: P0 | E68: FR-20 | F68: AC-12,AC-13,AC-15 | G68: D06,D07 | H68: 按主文档第5章构建独立数据快照；分别在补位、账单、outbox和COMMIT前注入失败 | I68: 业务全部回原OPEN和旧正式状态；任务失败与审计可记录 | J68: 构建/环境/数据版本、请求与traceId、前后数据库一致性快照；并发附屏障时间线，故障附注入与恢复日志 | K68: 自动化+人工核验 | L68: R1/R2 | M68: 《设计文档_V2.0》第6、8、附录A；业务约束见《需求分析文档_V2.0》第5—7章 | N68: 列举的每个边界/枚举/时刻/浏览器组合均为必测variant；每variant留runId或参数化子结果，全部通过才可将整条标PASS
A69: TC-CLOSE-011 | B69: CLOSE | C69: 关闭提交后进程中断 | D69: P0 | E69: FR-20 | F69: AC-12,AC-13,AC-15 | G69: D06,D07 | H69: 按主文档第5章构建独立数据快照；LOCAL_COMMITTED后、发计费前终止进程再启动 | I69: CLOSED和最终课表保留；outbox恢复；不重复结算 | J69: 构建/环境/数据版本、请求与traceId、前后数据库一致性快照；并发附屏障时间线，故障附注入与恢复日志 | K69: 自动化+人工核验 | L69: R1/R2 | M69: 《设计文档_V2.0》第6、8、附录A；业务约束见《需求分析文档_V2.0》第5—7章 | N69: 列举的每个边界/枚举/时刻/浏览器组合均为必测variant；每variant留runId或参数化子结果，全部通过才可将整条标PASS
...

Sheet 执行记录
A1: 用例编号 | B1: runId | C1: 构建版本 | D1: 环境编号 | E1: 数据快照 | F1: 执行人 | G1: 当前状态 | H1: 实际结果 | I1: 缺陷编号 | J1: 证据路径 | K1: 执行时间 | L1: 备注
A2: TC-AUTH-001 | B2: RC-AUTO-2026-10-07 | C2: V0.2.0候选（分阶段构建，见证据时间） | D2: Win/Java21/MySQL8.4/Chrome | E2: registration_test；browser基线使用demo | F2: Codex自动执行 | G2: PARTIAL | H2: 已执行关联场景；未覆盖所有必测variant | J2: 验收证据/browser.json;验收证据/integration.json | K2: 2026-10-06T16:57:56.747Z | L2: 全变体通过且成员复核后才能标整条PASS；自动执行不代替人工签名
A3: TC-AUTH-002 | B3: RC-AUTO-2026-10-07 | C3: V0.2.0候选（分阶段构建，见证据时间） | D3: Win/Java21/MySQL8.4/Chrome | E3: registration_test；browser基线使用demo | F3: Codex自动执行 | G3: PARTIAL | H3: 已执行关联场景；未覆盖所有必测variant | J3: 验收证据/acceptance.json;验收证据/integration.json | K3: 2026-10-06T16:45:38.735388+00:00 | L3: 全变体通过且成员复核后才能标整条PASS；自动执行不代替人工签名
A4: TC-AUTH-003 | B4: RC-AUTO-2026-10-07 | C4: V0.2.0候选（分阶段构建，见证据时间） | D4: Win/Java21/MySQL8.4/Chrome | E4: registration_test；browser基线使用demo | F4: Codex自动执行 | G4: PARTIAL | H4: 已执行关联场景；未覆盖所有必测variant | J4: 验收证据/integration.json | K4: 2026-10-06T16:45:13.806207+00:00 | L4: 全变体通过且成员复核后才能标整条PASS；自动执行不代替人工签名
A5: TC-AUTH-004 | G5: NOT_RUN
A6: TC-AUTH-005 | G6: NOT_RUN
A7: TC-AUTH-006 | B7: RC-AUTO-2026-10-07 | C7: V0.2.0候选（分阶段构建，见证据时间） | D7: Win/Java21/MySQL8.4/Chrome | E7: registration_test；browser基线使用demo | F7: Codex自动执行 | G7: PARTIAL | H7: 已执行关联场景；未覆盖所有必测variant | J7: 验收证据/acceptance.json | K7: 2026-10-06T16:45:38.735388+00:00 | L7: 全变体通过且成员复核后才能标整条PASS；自动执行不代替人工签名
A8: TC-AUTH-007 | G8: NOT_RUN
A9: TC-AUTH-008 | G9: NOT_RUN
A10: TC-CAT-001 | B10: RC-AUTO-2026-10-07 | C10: V0.2.0候选（分阶段构建，见证据时间） | D10: Win/Java21/MySQL8.4/Chrome | E10: registration_test；browser基线使用demo | F10: Codex自动执行 | G10: PARTIAL | H10: 已执行关联场景；未覆盖所有必测variant | J10: 验收证据/browser.json;验收证据/integration.json | K10: 2026-10-06T16:57:56.747Z | L10: 全变体通过且成员复核后才能标整条PASS；自动执行不代替人工签名
A11: TC-CAT-002 | B11: RC-AUTO-2026-10-07 | C11: V0.2.0候选（分阶段构建，见证据时间） | D11: Win/Java21/MySQL8.4/Chrome | E11: registration_test；browser基线使用demo | F11: Codex自动执行 | G11: PARTIAL | H11: 已执行关联场景；未覆盖所有必测variant | J11: 验收证据/acceptance.json | K11: 2026-10-06T16:45:38.735388+00:00 | L11: 全变体通过且成员复核后才能标整条PASS；自动执行不代替人工签名
A12: TC-CAT-003 | G12: NOT_RUN
A13: TC-CAT-004 | B13: RC-AUTO-2026-10-07 | C13: V0.2.0候选（分阶段构建，见证据时间） | D13: Win/Java21/MySQL8.4/Chrome | E13: registration_test；browser基线使用demo | F13: Codex自动执行 | G13: PARTIAL | H13: 已执行关联场景；未覆盖所有必测variant | J13: 验收证据/acceptance.json | K13: 2026-10-06T16:45:38.735388+00:00 | L13: 全变体通过且成员复核后才能标整条PASS；自动执行不代替人工签名
A14: TC-CAT-005 | B14: RC-AUTO-2026-10-07 | C14: V0.2.0候选（分阶段构建，见证据时间） | D14: Win/Java21/MySQL8.4/Chrome | E14: registration_test；browser基线使用demo | F14: Codex自动执行 | G14: PARTIAL | H14: 已执行关联场景；未覆盖所有必测variant | J14: 验收证据/acceptance.json | K14: 2026-10-06T16:45:38.735388+00:00 | L14: 全变体通过且成员复核后才能标整条PASS；自动执行不代替人工签名
A15: TC-CAT-006 | G15: NOT_RUN
A16: TC-REG-001 | B16: RC-AUTO-2026-10-07 | C16: V0.2.0候选（分阶段构建，见证据时间） | D16: Win/Java21/MySQL8.4/Chrome | E16: registration_test；browser基线使用demo | F16: Codex自动执行 | G16: PARTIAL | H16: 已执行关联场景；未覆盖所有必测variant | J16: 验收证据/browser.json;验收证据/integration.json | K16: 2026-10-06T16:57:56.747Z | L16: 全变体通过且成员复核后才能标整条PASS；自动执行不代替人工签名
A17: TC-REG-002 | B17: RC-AUTO-2026-10-07 | C17: V0.2.0候选（分阶段构建，见证据时间） | D17: Win/Java21/MySQL8.4/Chrome | E17: registration_test；browser基线使用demo | F17: Codex自动执行 | G17: PARTIAL | H17: 已执行关联场景；未覆盖所有必测variant | J17: 验收证据/acceptance.json | K17: 2026-10-06T16:45:38.735388+00:00 | L17: 全变体通过且成员复核后才能标整条PASS；自动执行不代替人工签名
A18: TC-REG-003 | B18: RC-AUTO-2026-10-07 | C18: V0.2.0候选（分阶段构建，见证据时间） | D18: Win/Java21/MySQL8.4/Chrome | E18: registration_test；browser基线使用demo | F18: Codex自动执行 | G18: PARTIAL | H18: 已执行关联场景；未覆盖所有必测variant | J18: 验收证据/browser.json;验收证据/integration.json;验收证据/rehearsal.json | K18: 2026-10-06T16:57:56.747Z | L18: 全变体通过且成员复核后才能标整条PASS；自动执行不代替人工签名
A19: TC-REG-004 | B19: RC-AUTO-2026-10-07 | C19: V0.2.0候选（分阶段构建，见证据时间） | D19: Win/Java21/MySQL8.4/Chrome | E19: registration_test；browser基线使用demo | F19: Codex自动执行 | G19: PARTIAL | H19: 已执行关联场景；未覆盖所有必测variant | J19: 验收证据/acceptance.json | K19: 2026-10-06T16:45:38.735388+00:00 | L19: 全变体通过且成员复核后才能标整条PASS；自动执行不代替人工签名
A20: TC-REG-005 | G20: NOT_RUN
A21: TC-REG-006 | B21: RC-AUTO-2026-10-07 | C21: V0.2.0候选（分阶段构建，见证据时间） | D21: Win/Java21/MySQL8.4/Chrome | E21: registration_test；browser基线使用demo | F21: Codex自动执行 | G21: PARTIAL | H21: 已执行关联场景；未覆盖所有必测variant | J21: 验收证据/acceptance.json;验收证据/integration.json | K21: 2026-10-06T16:45:38.735388+00:00 | L21: 全变体通过且成员复核后才能标整条PASS；自动执行不代替人工签名
A22: TC-REG-007 | B22: RC-AUTO-2026-10-07 | C22: V0.2.0候选（分阶段构建，见证据时间） | D22: Win/Java21/MySQL8.4/Chrome | E22: registration_test；browser基线使用demo | F22: Codex自动执行 | G22: PARTIAL | H22: 已执行关联场景；未覆盖所有必测variant | J22: 验收证据/acceptance.json | K22: 2026-10-06T16:45:38.735388+00:00 | L22: 全变体通过且成员复核后才能标整条PASS；自动执行不代替人工签名
A23: TC-REG-008 | B23: RC-AUTO-2026-10-07 | C23: V0.2.0候选（分阶段构建，见证据时间） | D23: Win/Java21/MySQL8.4/Chrome | E23: registration_test；browser基线使用demo | F23: Codex自动执行 | G23: PARTIAL | H23: 已执行关联场景；未覆盖所有必测variant | J23: 验收证据/algorithm-unit.xml | K23: 2026-10-07 | L23: 全变体通过且成员复核后才能标整条PASS；自动执行不代替人工签名
A24: TC-REG-009 | B24: RC-AUTO-2026-10-07 | C24: V0.2.0候选（分阶段构建，见证据时间） | D24: Win/Java21/MySQL8.4/Chrome | E24: registration_test；browser基线使用demo | F24: Codex自动执行 | G24: PARTIAL | H24: 已执行关联场景；未覆盖所有必测variant | J24: 验收证据/acceptance.json | K24: 2026-10-06T16:45:38.735388+00:00 | L24: 全变体通过且成员复核后才能标整条PASS；自动执行不代替人工签名
A25: TC-REG-010 | G25: NOT_RUN
A26: TC-REG-011 | G26: NOT_RUN
A27: TC-REG-012 | G27: NOT_RUN
A28: TC-REG-013 | B28: RC-AUTO-2026-10-07 | C28: V0.2.0候选（分阶段构建，见证据时间） | D28: Win/Java21/MySQL8.4/Chrome | E28: registration_test；browser基线使用demo | F28: Codex自动执行 | G28: PARTIAL | H28: 已执行关联场景；未覆盖所有必测variant | J28: 验收证据/browser.json | K28: 2026-10-06T16:57:56.747Z | L28: 全变体通过且成员复核后才能标整条PASS；自动执行不代替人工签名
A29: TC-REG-014 | B29: RC-AUTO-2026-10-07 | C29: V0.2.0候选（分阶段构建，见证据时间） | D29: Win/Java21/MySQL8.4/Chrome | E29: registration_test；browser基线使用demo | F29: Codex自动执行 | G29: PARTIAL | H29: 已执行关联场景；未覆盖所有必测variant | J29: 验收证据/integration.json;验收证据/rehearsal.json | K29: 2026-10-06T16:57:49.954Z | L29: 全变体通过且成员复核后才能标整条PASS；自动执行不代替人工签名
A30: TC-REG-015 | B30: RC-AUTO-2026-10-07 | C30: V0.2.0候选（分阶段构建，见证据时间） | D30: Win/Java21/MySQL8.4/Chrome | E30: registration_test；browser基线使用demo | F30: Codex自动执行 | G30: PARTIAL | H30: 已执行关联场景；未覆盖所有必测variant | J30: 验收证据/integration.json | K30: 2026-10-06T16:45:13.806207+00:00 | L30: 全变体通过且成员复核后才能标整条PASS；自动执行不代替人工签名
A31: TC-REG-016 | B31: RC-AUTO-2026-10-07 | C31: V0.2.0候选（分阶段构建，见证据时间） | D31: Win/Java21/MySQL8.4/Chrome | E31: registration_test；browser基线使用demo | F31: Codex自动执行 | G31: PARTIAL | H31: 已执行关联场景；未覆盖所有必测variant | J31: 验收证据/integration.json | K31: 2026-10-06T16:45:13.806207+00:00 | L31: 全变体通过且成员复核后才能标整条PASS；自动执行不代替人工签名
A32: TC-TEA-001 | B32: RC-AUTO-2026-10-07 | C32: V0.2.0候选（分阶段构建，见证据时间） | D32: Win/Java21/MySQL8.4/Chrome | E32: registration_test；browser基线使用demo | F32: Codex自动执行 | G32: PARTIAL | H32: 已执行关联场景；未覆盖所有必测variant | J32: 验收证据/browser.json | K32: 2026-10-06T16:57:56.747Z | L32: 全变体通过且成员复核后才能标整条PASS；自动执行不代替人工签名
A33: TC-TEA-002 | G33: NOT_RUN
A34: TC-TEA-003 | B34: RC-AUTO-2026-10-07 | C34: V0.2.0候选（分阶段构建，见证据时间） | D34: Win/Java21/MySQL8.4/Chrome | E34: registration_test；browser基线使用demo | F34: Codex自动执行 | G34: PARTIAL | H34: 已执行关联场景；未覆盖所有必测variant | J34: 验收证据/algorithm-unit.xml | K34: 2026-10-07 | L34: 全变体通过且成员复核后才能标整条PASS；自动执行不代替人工签名
A35: TC-TEA-004 | G35: NOT_RUN
A36: TC-TEA-005 | G36: NOT_RUN
A37: TC-TEA-006 | G37: NOT_RUN
A38: TC-GRADE-001 | B38: RC-AUTO-2026-10-07 | C38: V0.2.0候选（分阶段构建，见证据时间） | D38: Win/Java21/MySQL8.4/Chrome | E38: registration_test；browser基线使用demo | F38: Codex自动执行 | G38: PARTIAL | H38: 已执行关联场景；未覆盖所有必测variant | J38: 验收证据/acceptance.json;验收证据/browser.json;验收证据/integration.json;验收证据/rehearsal.json | K38: 2026-10-06T16:57:56.747Z | L38: 全变体通过且成员复核后才能标整条PASS；自动执行不代替人工签名
A39: TC-GRADE-002 | B39: RC-AUTO-2026-10-07 | C39: V0.2.0候选（分阶段构建，见证据时间） | D39: Win/Java21/MySQL8.4/Chrome | E39: registration_test；browser基线使用demo | F39: Codex自动执行 | G39: PARTIAL | H39: 已执行关联场景；未覆盖所有必测variant | J39: 验收证据/acceptance.json;验收证据/integration.json | K39: 2026-10-06T16:45:38.735388+00:00 | L39: 全变体通过且成员复核后才能标整条PASS；自动执行不代替人工签名
A40: TC-GRADE-003 | B40: RC-AUTO-2026-10-07 | C40: V0.2.0候选（分阶段构建，见证据时间） | D40: Win/Java21/MySQL8.4/Chrome | E40: registration_test；browser基线使用demo | F40: Codex自动执行 | G40: PARTIAL | H40: 已执行关联场景；未覆盖所有必测variant | J40: 验收证据/integration.json | K40: 2026-10-06T16:45:13.806207+00:00 | L40: 全变体通过且成员复核后才能标整条PASS；自动执行不代替人工签名
...

Sheet 执行历史
A1: 用例编号 | B1: runId | C1: 构建版本 | D1: 环境编号 | E1: 数据快照 | F1: 执行人 | G1: 当前状态 | H1: 实际结果 | I1: 缺陷编号 | J1: 证据路径 | K1: 执行时间 | L1: 备注

Sheet 追踪矩阵
A1: 需求或验收编号 | B1: 关联用例 | C1: 决策基线 | D1: 计划覆盖状态 | E1: 实际覆盖或缺口
A2: FR-01 | B2: TC-AUTH-001, TC-AUTH-002, TC-AUTH-007, TC-AUTH-008 | C2: 需求与设计V2.0 | D2: 已建立计划关联；实际执行见执行记录
A3: FR-02 | B3: TC-AUTH-001, TC-AUTH-008, TC-SEC-001, TC-UI-001 | C3: 需求与设计V2.0 | D3: 已建立计划关联；实际执行见执行记录
A4: FR-03 | B4: TC-AUTH-003, TC-SEC-008 | C4: 需求与设计V2.0 | D4: 已建立计划关联；实际执行见执行记录
A5: FR-04 | B5: TC-CAT-001, TC-CAT-002, TC-API-003 | C5: 需求与设计V2.0 | D5: 已建立计划关联；实际执行见执行记录
A6: FR-05 | B6: TC-REG-001, TC-REG-002, TC-REG-004 | C6: 需求与设计V2.0 | D6: 已建立计划关联；实际执行见执行记录
A7: FR-06 | B7: TC-REG-001, TC-REG-002, TC-REG-013, TC-UI-002 | C7: 需求与设计V2.0 | D7: 已建立计划关联；实际执行见执行记录
A8: FR-07 | B8: TC-REG-003, TC-REG-005, TC-REG-006, TC-REG-007, TC-REG-008, TC-REG-009, TC-REG-010, TC-REG-015, TC-REG-016, TC-CON-001, TC-DB-007, TC-DB-008 | C8: 需求与设计V2.0 | D8: 已建立计划关联；实际执行见执行记录
A9: FR-08 | B9: TC-REG-011, TC-REG-014, TC-REG-015, TC-CON-002, TC-CON-003, TC-DB-007 | C9: 需求与设计V2.0 | D9: 已建立计划关联；实际执行见执行记录
A10: FR-09 | B10: TC-REG-012, TC-UI-004 | C10: 需求与设计V2.0 | D10: 已建立计划关联；实际执行见执行记录
A11: FR-10 | B11: TC-REG-001, TC-REG-003, TC-REG-011, TC-REG-012, TC-REG-013, TC-UI-002 | C11: 需求与设计V2.0 | D11: 已建立计划关联；实际执行见执行记录
A12: FR-11 | B12: TC-TEA-001, TC-TEA-002 | C12: 需求与设计V2.0 | D12: 已建立计划关联；实际执行见执行记录
A13: FR-12 | B13: TC-TEA-001, TC-TEA-002, TC-TEA-003, TC-TEA-004, TC-TEA-005, TC-TEA-006, TC-CON-004, TC-CON-005 | C13: 需求与设计V2.0 | D13: 已建立计划关联；实际执行见执行记录
... A79: AC-17 | B79: TC-PERF-001, TC-PERF-002, TC-PERF-003, TC-PERF-004, TC-PERF-005, TC-PERF-006, TC-PERF-007, TC-PERF-008, TC-PERF-009 | C79: 需求与设计V2.0 | D79: 已建立计划关联；实际执行见执行记录

Sheet 数据集
A1: 编号 | B1: 数据范围 | C1: 构造与约束
A2: D01 基础闭环 | B2: 三角色、当前/上一完成学期、6个候选班、资格 | C2: 所有账号初始改密完成；常规窗口OPEN；主选时间互不冲突
A3: D02 时钟窗口 | B3: registration与add/drop起止边界 | C3: 注入应用Clock，不修改Windows系统时钟；开始前/开始/结束前/结束
A4: D03 时间矩阵 | B4: 相邻、重叠、单双周、日期不相交、非法跨午夜 | C4: 基于日期、week_mask、星期及本地时间，含学期首周边界
A5: D04 先修矩阵 | B5: A/B/C/D/F/I/null、缺失、多个先修 | C5: 先修成绩在此前已完成学期；同课程不同快照稳定ID
A6: D05 容量竞争 | B6: 9人/10人班、至少30独立申请者 | C6: 每申请者其他3主选独立或充分有名额，避免其他班先失败
A7: D06 关闭补位 | B7: 2/3/10人、无教师、有序备选、首次提交排序 | C7: 参与者曾完整首次提交，后经add/drop形成目标状态；含独立锚定学生
A8: D07 关闭故障 | B8: 事务写入检查点、任务租约、前后快照 | C8: 中断后可恢复，同学期仅一个逻辑任务
A9: D08 计费故障 | B9: 持久收件表、业务键、payload hash、丢响应/超时/重复 | C9: 计费Mock与业务库分开，停止响应不抹去已接收记录
A10: D09 成绩历史 | B10: 上一完成学期两教师不同班、空/已有成绩 | C10: 历史教授归属固定，ACTIVE历史名单，账号/成绩version
A11: D10 人员 | B11: 新增、原字段、SSN、状态、历史/当前关联、逻辑删除 | C11: 账号与人员同事务，当前关联删除必须拒绝
A12: D11 压力池 | B12: 500/2000独立活动会话及更多可用数据 | C12: 分散名额/版本热点，按业务集合循环，详见第9章
... A15: D14 认证支持 | B15: must_change_password、credential_version、多个会话 | C15: 改密/重置/删除后旧会话拒绝；凭据不进入日志

Sheet 环境登记
A1: 环境编号 | B1: 用途 | C1: 构建/提交 | D1: 服务拓扑 | E1: CPU/内存/磁盘 | F1: DB版本及参数 | G1: 工具/浏览器版本 | H1: Session策略 | I1: 数据快照 | J1: 登记人/日期 | K1: 核验结论

Sheet 缺陷台账
A1: 缺陷编号 | B1: 标题 | C1: 关联用例/runId | D1: 严重级别 | E1: 优先级 | F1: 构建环境 | G1: 复现步骤 | H1: 预期/实际 | I1: 证据 | J1: 责任人 | K1: 状态 | L1: 修复构建 | M1: 回归runId | N1: 风险或延期结论
A2: DEF-A01 | B2: 大目录全量加载再分页 | C2: A14/500-short | D2: S3 | E2: P1 | F2: Windows本机验收修订版 | G2: 大目录全量加载再分页 | H2: 预期符合业务/脚本同步；实际见首次失败或代码检查 | I2: 验收证据/A14；mixed-load.json | J2: Codex自动修复 | K2: 自动修复并复测；待成员核验 | L2: V0.2.0验收候选 | M2: A14/500-short | N2: SQL分页
A3: DEF-A02 | B3: 重置密码手输账号ID难以使用 | C3: A10/B03 | D3: S3 | E3: P1 | F3: Windows本机验收修订版 | G3: 重置密码手输账号ID难以使用 | H3: 预期符合业务/脚本同步；实际见首次失败或代码检查 | I3: 验收证据/acceptance.json；rehearsal.json | J3: Codex自动修复 | K3: 自动修复并复测；待成员核验 | L3: V0.2.0验收候选 | M3: A10/B03 | N3: 人员行安全关联重置
A4: DEF-A03 | B4: 切历史班可丢未保存成绩 | C4: B02 | D4: S3 | E4: P1 | F4: Windows本机验收修订版 | G4: 切历史班可丢未保存成绩 | H4: 预期符合业务/脚本同步；实际见首次失败或代码检查 | I4: 验收证据/rehearsal.json | J4: Codex自动修复 | K4: 自动修复并复测；待成员核验 | L4: V0.2.0验收候选 | M4: B02 | N4: 切班确认及取消恢复
A5: DEF-A04 | B5: 重启测试子进程输出管道挂起 | C5: R01/R02 | D5: S4 | E5: P2 | F5: Windows本机验收修订版 | G5: 重启测试子进程输出管道挂起 | H5: 预期符合业务/脚本同步；实际见首次失败或代码检查 | I5: 验收证据/restart-recovery.json | J5: Codex自动修复 | K5: 自动修复并复测；待成员核验 | L5: V0.2.0验收候选 | M5: R01/R02 | N5: 输出DEVNULL避免管道继承
A6: DEF-A05 | B6: 目录请求10秒无总延迟余量 | C6: A13 | D6: S3 | E6: P1 | F6: Windows本机验收修订版 | G6: 目录请求10秒无总延迟余量 | H6: 预期符合业务/脚本同步；实际见首次失败或代码检查 | I6: 验收证据/acceptance.json | J6: Codex自动修复 | K6: 自动修复并复测；待成员核验 | L6: V0.2.0验收候选 | M6: A13 | N6: 内部请求预算9秒
A7: DEF-A06 | B7: 默认确认框按钮英文 | C7: B02 | D7: S4 | E7: P2 | F7: Windows本机验收修订版 | G7: 默认确认框按钮英文 | H7: 预期符合业务/脚本同步；实际见首次失败或代码检查 | I7: 验收证据/rehearsal-first-failure.json；rehearsal.json | J7: Codex自动修复 | K7: 自动修复并复测；待成员核验 | L7: V0.2.0验收候选 | M7: B02 | N7: 中文语言包
A8: DEF-A07 | B8: 登录完成前脚本发保护请求 | C8: B06 | D8: S4 | E8: P2 | F8: Windows本机验收修订版 | G8: 登录完成前脚本发保护请求 | H8: 预期符合业务/脚本同步；实际见首次失败或代码检查 | I8: 验收证据/rehearsal-second-failure.json；rehearsal.json | J8: Codex自动修复 | K8: 自动修复并复测；待成员核验 | L8: V0.2.0验收候选 | M8: B06 | N8: 等待角色路由及身份标识

Sheet 性能轮次
A1: 轮次 | B1: 规划 | C1: 实际并发 | D1: 实例及共享DB | E1: 构建/数据 | F1: 工具配置 | G1: 稳态时长 | H1: 总尝试 | I1: 成功且<=120秒 | J1: 达标比例 | K1: 技术失败数 | L1: 业务冲突数 | M1: 目录最坏秒 | N1: 资源证据 | O1: 结论
A2: L0 | B2: 基准 | O2: NOT_RUN
A3: L1 | B3: 单实例100/300/500 | O3: NOT_RUN
A4: L2 | B4: 共享DB500/1000/2000 | O4: NOT_RUN
A5: L3 | B5: 代表轮次独立复测两次 | O5: NOT_RUN
A6: L4 | B6: 热点竞争 | O6: NOT_RUN
A7: L5 | B7: 故障降级独立 | O7: NOT_RUN
A8: L6 | B8: 60分钟稳定 | O8: NOT_RUN

Sheet 可用性记录
A1: 时间戳 | B1: 环境构建 | C1: 探测入口 | D1: 状态UP/DOWN/UNKNOWN | E1: 响应时长 | F1: 核心DB断言 | G1: 计费降级 | H1: 维护窗口 | I1: 证据 | J1: 备注

Sheet 发布检查单
A1: 编号 | B1: 检查项 | C1: 状态 | D1: 实际结果或缺口 | E1: 责任人 | F1: 证据 | G1: 日期
A2: RC-01 | B2: 冻结commit/tag且可空环境构建 | C2: NOT_RUN
A3: RC-02 | B3: 迁移checksum与初始化升级 | C3: NOT_RUN
A4: RC-03 | B4: 目录/Billing Mock版本及持久去重 | C4: NOT_RUN
A5: RC-04 | B5: 虚构数据与三角色账号 | C5: NOT_RUN
A6: RC-05 | B6: 全P0功能与API契约 | C6: NOT_RUN
A7: RC-06 | B7: 真实DB约束和回滚 | C7: NOT_RUN
A8: RC-07 | B8: 最后一席及教师并发 | C8: NOT_RUN
A9: RC-08 | B9: 对象越权与CSRF/会话 | C9: NOT_RUN
A10: RC-09 | B10: 关闭BUSY和重复任务 | C10: NOT_RUN
A11: RC-10 | B11: LEVELING固定场景及顺序 | C11: NOT_RUN
A12: RC-11 | B12: Billing丢响应/确认写失败/重启/旧token | C12: NOT_RUN
A13: RC-12 | B13: 数据巡检与外部全量对账 | C13: NOT_RUN
... A21: RC-20 | B21: AI辅助核验/成员贡献/签名 | C21: NOT_RUN

Sheet 风险台账
A1: 风险编号 | B1: 风险 | C1: 影响I1-5 | D1: 可能性L1-5 | E1: 难检测D1-5 | F1: 排序分 | G1: 优先级 | H1: 责任人 | I1: 缓解与测试入口 | J1: 实际状态 | K1: 证据或限制
A2: RISK-01 | B2: 并发超员 | F2: =IF(COUNT(C2:E2)=3,PRODUCT(C2:E2),"") | G2: P0 | J2: 待评审
A3: RISK-02 | B3: 选退课部分提交 | F3: =IF(COUNT(C3:E3)=3,PRODUCT(C3:E3),"") | G3: P0 | J3: 待评审
A4: RISK-03 | B4: 关闭与普通写交错 | F4: =IF(COUNT(C4:E4)=3,PRODUCT(C4:E4),"") | G4: P0 | J4: 待评审
A5: RISK-04 | B5: LEVELING顺序不确定 | F5: =IF(COUNT(C5:E5)=3,PRODUCT(C5:E5),"") | G5: P0 | J5: 待评审
A6: RISK-05 | B6: 重复收费或丢账单 | F6: =IF(COUNT(C6:E6)=3,PRODUCT(C6:E6),"") | G6: P0 | J6: 待评审
A7: RISK-06 | B7: 对象越权和成绩泄露 | F7: =IF(COUNT(C7:E7)=3,PRODUCT(C7:E7),"") | G7: P0 | J7: 待评审
A8: RISK-07 | B8: 旧版本覆盖 | F8: =IF(COUNT(C8:E8)=3,PRODUCT(C8:E8),"") | G8: P0 | J8: 待评审
A9: RISK-08 | B9: 删除破坏历史 | F9: =IF(COUNT(C9:E9)=3,PRODUCT(C9:E9),"") | G9: P0 | J9: 待评审
A10: RISK-09 | B10: 目录故障或缓存混用 | F10: =IF(COUNT(C10:E10)=3,PRODUCT(C10:E10),"") | G10: P0 | J10: 待评审
A11: RISK-10 | B11: 负载数据耗尽/发生器饱和 | F11: =IF(COUNT(C11:E11)=3,PRODUCT(C11:E11),"") | G11: P1 | J11: 待评审
A12: RISK-11 | B12: 七天观测不足 | F12: =IF(COUNT(C12:E12)=3,PRODUCT(C12:E12),"") | G12: P1 | J12: 待评审
A13: RISK-12 | B13: Mock丢失回执 | F13: =IF(COUNT(C13:E13)=3,PRODUCT(C13:E13),"") | G13: P1 | J13: 待评审
... A15: RISK-14 | B15: 接口/DDL漂移 | F15: =IF(COUNT(C15:E15)=3,PRODUCT(C15:E15),"") | G15: P1 | J15: 待评审

Sheet 报告结构
A1: 章节 | B1: 必须填写内容 | C1: 实际内容/证据
A2: 1 | B2: 执行摘要和实际版本
A3: 2 | B3: 范围及变更
A4: 3 | B4: 环境与fixture
A5: 4 | B5: 执行覆盖及参数化完整性
A6: 5 | B6: 功能/契约/数据库/安全结果
A7: 6 | B7: 并发/关闭/计费恢复结果
A8: 7 | B8: 浏览器兼容
A9: 8 | B9: 性能实际值和目标缺口
A10: 9 | B10: 可用性窗口/覆盖/上下界
A11: 10 | B11: 缺陷与遗留风险
A12: 11 | B12: 一致性巡检和对账
A13: 12 | B13: 放行建议与限制
A14: 13 | B14: 证据索引及核验签名

Sheet 自动场景证据
A1: 套件 | B1: 场景 | C1: 标题 | D1: 结果 | E1: 关联计划用例 | F1: 证据 | G1: 实际执行时间 | H1: 执行性质
A2: integration | B2: TC-AUTH-001 | C2: 三角色登录 | D2: PASS | E2: TC-AUTH-001 | F2: 验收证据/integration.json | G2: 2026-10-06T16:45:13.806207+00:00 | H2: 自动执行；非人工验收
A3: integration | B3: TC-AUTH-002 | C3: 错误凭据拒绝 | D3: PASS | E3: TC-AUTH-002 | F3: 验收证据/integration.json | G3: 2026-10-06T16:45:13.806207+00:00 | H3: 自动执行；非人工验收
A4: integration | B4: TC-SEC-002 | C4: 真实CSRF过滤链拒绝 | D4: PASS | E4: TC-SEC-002 | F4: 验收证据/integration.json | G4: 2026-10-06T16:45:13.806207+00:00 | H4: 自动执行；非人工验收
A5: integration | B5: TC-SEC-001 | C5: 角色越权拒绝 | D5: PASS | E5: TC-SEC-001 | F5: 验收证据/integration.json | G5: 2026-10-06T16:45:13.806207+00:00 | H5: 自动执行；非人工验收
A6: integration | B6: TC-CAT-001 | C6: 冻结目录字段和ID字符串 | D6: PASS | E6: TC-CAT-001 | F6: 验收证据/integration.json | G6: 2026-10-06T16:45:13.806207+00:00 | H6: 自动执行；非人工验收
A7: integration | B7: TC-API-003 | C7: 分页及非法排序 | D7: PASS | E7: TC-API-003 | F7: 验收证据/integration.json | G7: 2026-10-06T16:45:13.806207+00:00 | H7: 自动执行；非人工验收
A8: integration | B8: TC-REG-001 | C8: 草稿不占名额 | D8: PASS | E8: TC-REG-001 | F8: 验收证据/integration.json | G8: 2026-10-06T16:45:13.806207+00:00 | H8: 自动执行；非人工验收
A9: integration | B9: TC-REG-003 | C9: 首次4+2正式提交 | D9: PASS | E9: TC-REG-003 | F9: 验收证据/integration.json | G9: 2026-10-06T16:45:13.806207+00:00 | H9: 自动执行；非人工验收
A10: integration | B10: TC-REG-016 | C10: 成功重放与异体冲突 | D10: PASS | E10: TC-REG-016 | F10: 验收证据/integration.json | G10: 2026-10-06T16:45:13.806207+00:00 | H10: 自动执行；非人工验收
A11: integration | B11: TC-REG-015 | C11: 旧版本拒绝 | D11: PASS | E11: TC-REG-015 | F11: 验收证据/integration.json | G11: 2026-10-06T16:45:13.806207+00:00 | H11: 自动执行；非人工验收
A12: integration | B12: TC-REG-006 | C12: 先修F拒绝且全量回滚 | D12: PASS | E12: TC-REG-006 | F12: 验收证据/integration.json | G12: 2026-10-06T16:45:13.806207+00:00 | H12: 自动执行；非人工验收
... A19: integration | B19: TC-PEOPLE-004 | C19: 当前关联拒绝删除 | D19: PASS | E19: TC-PEOPLE-004 | F19: 验收证据/integration.json | G19: 2026-10-06T16:45:13.806207+00:00 | H19: 自动执行；非人工验收
A20: integration | B20: TC-REG-RECREATE | C20: 删除、草稿、重建仍须首次4+2 | D20: PASS | F20: 验收证据/integration.json | G20: 2026-10-06T16:45:13.806207+00:00 | H20: 自动执行；非人工验收
A21: integration | B21: TC-API-INTEGER | C21: 版本和选择顺序拒绝小数 | D21: PASS | F21: 验收证据/integration.json | G21: 2026-10-06T16:45:13.806207+00:00 | H21: 自动执行；非人工验收
A22: integration | B22: TC-TEACH-ATOMIC | C22: 授课集合原子修改与其他教师占用拒绝 | D22: PASS | F22: 验收证据/integration.json | G22: 2026-10-06T16:45:13.806207+00:00 | H22: 自动执行；非人工验收
A23: integration | B23: TC-GRADE-ROLLBACK | C23: 成绩批量中途失败回滚 | D23: PASS | F23: 验收证据/integration.json | G23: 2026-10-06T16:45:13.806207+00:00 | H23: 自动执行；非人工验收
A24: integration | B24: TC-CON-006 | C24: 普通写持锁时关闭任务BLOCKED_BUSY | D24: PASS | E24: TC-CON-006 | F24: 验收证据/integration.json | G24: 2026-10-06T16:45:13.806207+00:00 | H24: 自动执行；非人工验收
A25: integration | B25: TC-CLOSE-010 | C25: 本地关闭失败业务全部回滚 | D25: PASS | E25: TC-CLOSE-010 | F25: 验收证据/integration.json | G25: 2026-10-06T16:45:13.806207+00:00 | H25: 自动执行；非人工验收
A26: integration | B26: TC-CLOSE-001 | C26: 本地原子关闭和最终不变量 | D26: PASS | E26: TC-CLOSE-001 | F26: 验收证据/integration.json | G26: 2026-10-06T16:45:13.806207+00:00 | H26: 自动执行；非人工验收
A27: integration | B27: TC-BILL-003 | C27: 远端接收丢响应持久去重 | D27: PASS | E27: TC-BILL-003 | F27: 验收证据/integration.json | G27: 2026-10-06T16:45:13.806207+00:00 | H27: 自动执行；非人工验收
A28: integration | B28: TC-GRADE-007 | C28: 关闭后仍可历史评分 | D28: PASS | E28: TC-GRADE-007 | F28: 验收证据/integration.json | G28: 2026-10-06T16:45:13.806207+00:00 | H28: 自动执行；非人工验收
A29: integration | B29: TC-REG-014 | C29: 关闭后正式写拒绝 | D29: PASS | E29: TC-REG-014 | F29: 验收证据/integration.json | G29: 2026-10-06T16:45:13.806207+00:00 | H29: 自动执行；非人工验收
A30: integration | B30: TC-AUTH-003 | C30: 退出后会话失效 | D30: PASS | E30: TC-AUTH-003 | F30: 验收证据/integration.json | G30: 2026-10-06T16:45:13.806207+00:00 | H30: 自动执行；非人工验收
A31: acceptance | B31: A01 | C31: 错误、未知及空凭据 | D31: PASS | E31: TC-AUTH-002 | F31: 验收证据/acceptance.json | G31: 2026-10-06T16:45:38.735388+00:00 | H31: 自动执行；非人工验收
A32: acceptance | B32: A02 | C32: 跨角色和历史班访问拒绝 | D32: PASS | E32: TC-SEC-001,TC-GRADE-008,TC-PRIV-001 | F32: 验收证据/acceptance.json | G32: 2026-10-06T16:45:38.735388+00:00 | H32: 自动执行；非人工验收
A33: acceptance | B33: A03 | C33: 版本输入类型边界 | D33: PASS | E33: TC-API-006 | F33: 验收证据/acceptance.json | G33: 2026-10-06T16:45:38.735388+00:00 | H33: 自动执行；非人工验收
A34: acceptance | B34: A04 | C34: 首次数量和重复班/课程 | D34: PASS | E34: TC-REG-002,TC-REG-004,TC-REG-009 | F34: 验收证据/acceptance.json | G34: 2026-10-06T16:45:38.735388+00:00 | H34: 自动执行；非人工验收
A35: acceptance | B35: A05 | C35: F/I/未录入先修 | D35: PASS | E35: TC-REG-006,TC-REG-007 | F35: 验收证据/acceptance.json | G35: 2026-10-06T16:45:38.735388+00:00 | H35: 自动执行；非人工验收
... A61: rehearsal | B61: B06 | C61: 正常演示库仍OPEN且无脚本异常 | D61: PASS | E61: TC-CI-003 | F61: 验收证据/rehearsal.json | G61: 2026-10-06T16:57:49.954Z | H61: 自动执行；非人工验收

Sheet 实现验收对应
A1: 需求 | B1: 含义 | C1: 模块 | D1: 状态 | E1: 场景 | F1: 计划用例 | G1: 人工复核
A2: FR-01 | B2: 校验用户名和密码，成功建立登录状态，失败允许重试或取消 | C2: auth | D2: 有实现、部分自动场景通过；成员复核待完成 | E2: A01,BROWSER-1,TC-AUTH-001,TC-AUTH-002 | F2: TC-AUTH-001, TC-AUTH-002, TC-AUTH-007, TC-AUTH-008 | G2: 待成员填写签名/日期
A3: FR-02 | B3: 根据角色展示可用导航，不因此替代服务端授权 | C3: auth | D3: 有实现、部分自动场景通过；成员复核待完成 | E3: A02,BROWSER-1,BROWSER-4,BROWSER-8,TC-AUTH-001,TC-SEC-001 | F3: TC-AUTH-001, TC-AUTH-008, TC-SEC-001, TC-UI-001 | G3: 待成员填写签名/日期
A4: FR-03 | B4: 退出登录并使当前认证状态失效 | C4: auth | D4: 有实现、部分自动场景通过；成员复核待完成 | E4: TC-AUTH-003 | F4: TC-AUTH-003, TC-SEC-008 | G4: 待成员填写签名/日期
A5: FR-04 | B5: 查询当前学期开课班及课程、院系、教师、时间和先修信息 | C5: catalog | D5: 有实现、部分自动场景通过；成员复核待完成 | E5: A14,BROWSER-1,TC-API-003,TC-CAT-001 | F5: TC-CAT-001, TC-CAT-002, TC-API-003 | G5: 待成员填写签名/日期
A6: FR-05 | B6: 学生创建一份当前学期课表，区分主选与有序备选 | C6: registration | D6: 有实现、部分自动场景通过；成员复核待完成 | E6: A04,BROWSER-2,TC-REG-001 | F6: TC-REG-001, TC-REG-002, TC-REG-004 | G6: 待成员填写签名/日期
A7: FR-06 | B7: 学生保存草稿，未正式加入班级的项目为 SELECTED | C7: registration | D7: 有实现、部分自动场景通过；成员复核待完成 | E7: A04,B01,BROWSER-2,BROWSER-3,TC-REG-001 | F7: TC-REG-001, TC-REG-002, TC-REG-013, TC-UI-002 | G7: 待成员填写签名/日期
A8: FR-07 | B8: 正式提交前校验先修、开放、容量及时间，成功加入名单并标记 ENROLLED | C8: registration | D8: 有实现、部分自动场景通过；成员复核待完成 | E8: A04,A05,B01,BROWSER-3,TC-CON-001,TC-DB-008,TC-REG-003,TC-REG-006,TC-REG-015,TC-REG-016,adjacentAndDifferentTeachingWeeksDoNotConflict | F8: TC-REG-003, TC-REG-005, TC-REG-006, TC-REG-007, TC-REG-008, TC-REG-009, TC-REG-010, TC-REG-015, TC-REG-016, TC-CON-001, TC-DB-007, TC-DB-008 | G8: 待成员填写签名/日期
A9: FR-08 | B9: 在允许期间调整本人选课，并同步处理名单及名额 | C9: registration | D9: 有实现、部分自动场景通过；成员复核待完成 | E9: B05,TC-REG-014,TC-REG-015 | F9: TC-REG-011, TC-REG-014, TC-REG-015, TC-CON-002, TC-CON-003, TC-DB-007 | G9: 待成员填写签名/日期
A10: FR-09 | B10: 经确认删除本人课表，并移除已加入班级的关系 | C10: registration | D10: 有实现或设计映射；相关完整用例未执行 | E10: NOT_RUN | F10: TC-REG-012, TC-UI-004 | G10: 待成员填写签名/日期
A11: FR-10 | B11: 查看本人当前课表，显示主备选、注册结果、取消原因 | C11: registration | D11: 有实现、部分自动场景通过；成员复核待完成 | E11: B01,BROWSER-2,BROWSER-3,TC-REG-001,TC-REG-003 | F11: TC-REG-001, TC-REG-003, TC-REG-011, TC-REG-012, TC-REG-013, TC-UI-002 | G11: 待成员填写签名/日期
A12: FR-11 | B12: 教师查询有资格教授的班及本人已有授课选择 | C12: teaching | D12: 有实现、部分自动场景通过；成员复核待完成 | E12: BROWSER-5 | F12: TC-TEA-001, TC-TEA-002 | G12: 待成员填写签名/日期
... A79: AC-17 | B79: 在已记录环境和负载口径运行性能测试 | C79: shared / auth / business services | D79: 有实现、部分自动场景通过；成员复核待完成 | E79: 500-short | F79: TC-PERF-001, TC-PERF-002, TC-PERF-003, TC-PERF-004, TC-PERF-005, TC-PERF-006, TC-PERF-007, TC-PERF-008, TC-PERF-009 | G79: 待成员填写签名/日期

Sheet 成员验收签署
A1: 项 | B1: 执行人 | C1: 日期 | D1: 结果 | E1: 证据/备注
A2: 三角色全流程 | D2: 待人工执行 | E2: 自动证据可供参考，不能代签
A3: 异常输入/权限 | D3: 待人工执行 | E3: 自动证据可供参考，不能代签
A4: 满员/先修/时间冲突 | D4: 待人工执行 | E4: 自动证据可供参考，不能代签
A5: 关闭/计费最终状态 | D5: 待人工执行 | E5: 自动证据可供参考，不能代签
A6: 启动停止/重置/备份 | D6: 待人工执行 | E6: 自动证据可供参考，不能代签
A7: 核心架构与业务自主复核 | D7: 待人工执行 | E7: 自动证据可供参考，不能代签
A8: 贡献百分比核实 | D8: 待人工执行 | E8: 自动证据可供参考，不能代签
A9: AI使用标注核验 | D9: 待人工执行 | E9: 自动证据可供参考，不能代签
